Workbook

Sheet Cover
B2: PATHWAYS | D2: =About!B5 -> [Organization name]
B8: =INDEX(Guide!$C$21:$G$21,MATCH(About!$B$8,Guide!$C$20:$G$20,0)) -> MIDTERM REPORT
B9: =About!B6 -> Coastal Livelihoods Project
B10: =TEXT(About!B9,"d mmm yyyy")&" to "&TEXT(About!B10,"d mmm yyyy") -> 1 Oct 2025 to 30 Sep 2026
B11: =About!B7&" | "&'2 Background'!B10 -> CLP-2025-03 | Borongan, Guiuan, Salcedo and Mercedes, Eastern Samar
B15: Prepared for | C15: Programme donor and board of trustees
B16: Prepared by | C16: M&E Officer, Coastal Livelihoods Project
B17: Version | C17: v1.0
B18: Status | C18: Draft
B19: Generated | C19: =About!B20 -> 46302.446
B20: Confidentiality | C20: Internal
B23: Contents and section choices: Contents sheet. How the template works: Guide sheet.

Sheet About
A1: ="PATHWAYS | "&About!$B$7&" "&About!$B$6&" | "&About!$B$8&" report" -> PATHWAYS | CLP-2025-03 Coastal Livelihoods Project | Midterm report
A2: About this report
A3: Fixed section. Always present. States what the report covers so readers can trust and reuse the numbers.
A4: Item | B4: Value
A5: Organization | B5: [Organization name]
A6: Project title | B6: Coastal Livelihoods Project
A7: Project code | B7: CLP-2025-03
A8: Report preset | B8: Midterm
A9: Report period start | B9: 45931
A10: Report period end | B10: 46295
A11: Data cut-off | B11: 46295
A12: Project start | B12: 45931
A13: Project end | B13: 46660
A14: Timeline elapsed | B14: =MIN(1,MAX(0,(B11-B12)/(B13-B12))) -> 0.49931413
A15: Filter: location | B15: All municipalities
A16: Filter: indicator types | B16: All
A17: Filter: beneficiary segment | B17: All (aggregates only)
A18: Data sources | B18: Verified activity updates, indicator measurements, released beneficiary aggregates, approved expenses, signed-off evaluation, approved evidence
A19: Privacy | B19: Beneficiary figures are aggregates only. Any group under 5 people shows as "Fewer than 5". No names or contact details appear in this report.
A20: Generated | B20: 46302.446
A21: Sections included | B21: =COUNTIF(Contents!$E$8:$E$20,"Yes")&" of 13 optional sections, plus the fixed sections" -> 10 of 13 optional sections, plus the fixed sections

Sheet Contents
A1: ="PATHWAYS | "&About!$B$7&" "&About!$B$6&" | "&About!$B$8&" report" -> PATHWAYS | CLP-2025-03 Coastal Livelihoods Project | Midterm report
A2: Contents
A3: Fixed section. Set Include to Yes or No; numbering updates on every section sheet.
A5: No. | B5: Section | C5: Sheet | D5: Preset rule | E5: Include | F5: Check
B6: Cover | C6: Cover | D6: Always | E6: Yes
B7: About this report | C7: About | D7: Always | E7: Yes
A8: =IF(E8="Yes",COUNTIF($E$8:E8,"Yes"),"-") -> 1 | B8: Executive summary | C8: 1 Summary | D8: =INDEX(Guide!$C$22:$G$34,1,MATCH(About!$B$8,Guide!$C$20:$G$20,0)) -> Required | E8: Yes | F8: =IF(AND(D8="Required",E8<>"Yes"),"Required by this preset: set to Yes",IF(AND(D8="Not offered",E8="Yes"),"Not offered in this preset: set to No","OK")) -> OK
A9: =IF(E9="Yes",COUNTIF($E$8:E9,"Yes"),"-") -> 2 | B9: Project background | C9: 2 Background | D9: =INDEX(Guide!$C$22:$G$34,2,MATCH(About!$B$8,Guide!$C$20:$G$20,0)) -> Default | E9: Yes | F9: =IF(AND(D9="Required",E9<>"Yes"),"Required by this preset: set to Yes",IF(AND(D9="Not offered",E9="Yes"),"Not offered in this preset: set to No","OK")) -> OK
A10: =IF(E10="Yes",COUNTIF($E$8:E10,"Yes"),"-") -> 3 | B10: Status overview | C10: 3 Status | D10: =INDEX(Guide!$C$22:$G$34,3,MATCH(About!$B$8,Guide!$C$20:$G$20,0)) -> Default | E10: Yes | F10: =IF(AND(D10="Required",E10<>"Yes"),"Required by this preset: set to Yes",IF(AND(D10="Not offered",E10="Yes"),"Not offered in this preset: set to No","OK")) -> OK
A11: =IF(E11="Yes",COUNTIF($E$8:E11,"Yes"),"-") -> 4 | B11: Results and indicator performance | C11: 4 Indicators | D11: =INDEX(Guide!$C$22:$G$34,4,MATCH(About!$B$8,Guide!$C$20:$G$20,0)) -> Default | E11: Yes | F11: =IF(AND(D11="Required",E11<>"Yes"),"Required by this preset: set to Yes",IF(AND(D11="Not offered",E11="Yes"),"Not offered in this preset: set to No","OK")) -> OK
A12: =IF(E12="Yes",COUNTIF($E$8:E12,"Yes"),"-") -> 5 | B12: Activities and milestones | C12: 5 Activities | D12: =INDEX(Guide!$C$22:$G$34,5,MATCH(About!$B$8,Guide!$C$20:$G$20,0)) -> Default | E12: Yes | F12: =IF(AND(D12="Required",E12<>"Yes"),"Required by this preset: set to Yes",IF(AND(D12="Not offered",E12="Yes"),"Not offered in this preset: set to No","OK")) -> OK
A13: =IF(E13="Yes",COUNTIF($E$8:E13,"Yes"),"-") -> 6 | B13: Beneficiary reach | C13: 6 Reach | D13: =INDEX(Guide!$C$22:$G$34,6,MATCH(About!$B$8,Guide!$C$20:$G$20,0)) -> Default | E13: Yes | F13: =IF(AND(D13="Required",E13<>"Yes"),"Required by this preset: set to Yes",IF(AND(D13="Not offered",E13="Yes"),"Not offered in this preset: set to No","OK")) -> OK
A14: =IF(E14="Yes",COUNTIF($E$8:E14,"Yes"),"-") -> - | B14: Survey and assessment results | C14: 7 Assessment | D14: =INDEX(Guide!$C$22:$G$34,7,MATCH(About!$B$8,Guide!$C$20:$G$20,0)) -> Optional | E14: No | F14: =IF(AND(D14="Required",E14<>"Yes"),"Required by this preset: set to Yes",IF(AND(D14="Not offered",E14="Yes"),"Not offered in this preset: set to No","OK")) -> OK
A15: =IF(E15="Yes",COUNTIF($E$8:E15,"Yes"),"-") -> 7 | B15: Financial summary | C15: 8 Budget | D15: =INDEX(Guide!$C$22:$G$34,8,MATCH(About!$B$8,Guide!$C$20:$G$20,0)) -> Default | E15: Yes | F15: =IF(AND(D15="Required",E15<>"Yes"),"Required by this preset: set to Yes",IF(AND(D15="Not offered",E15="Yes"),"Not offered in this preset: set to No","OK")) -> OK
A16: =IF(E16="Yes",COUNTIF($E$8:E16,"Yes"),"-") -> 8 | B16: Evaluation | C16: 9 Evaluation | D16: =INDEX(Guide!$C$22:$G$34,9,MATCH(About!$B$8,Guide!$C$20:$G$20,0)) -> Default | E16: Yes | F16: =IF(AND(D16="Required",E16<>"Yes"),"Required by this preset: set to Yes",IF(AND(D16="Not offered",E16="Yes"),"Not offered in this preset: set to No","OK")) -> OK
A17: =IF(E17="Yes",COUNTIF($E$8:E17,"Yes"),"-") -> 9 | B17: Risks, issues and decisions | C17: 10 Risks | D17: =INDEX(Guide!$C$22:$G$34,10,MATCH(About!$B$8,Guide!$C$20:$G$20,0)) -> Default | E17: Yes | F17: =IF(AND(D17="Required",E17<>"Yes"),"Required by this preset: set to Yes",IF(AND(D17="Not offered",E17="Yes"),"Not offered in this preset: set to No","OK")) -> OK
A18: =IF(E18="Yes",COUNTIF($E$8:E18,"Yes"),"-") -> 10 | B18: Lessons learned and next steps | C18: 11 Lessons | D18: =INDEX(Guide!$C$22:$G$34,11,MATCH(About!$B$8,Guide!$C$20:$G$20,0)) -> Default | E18: Yes | F18: =IF(AND(D18="Required",E18<>"Yes"),"Required by this preset: set to Yes",IF(AND(D18="Not offered",E18="Yes"),"Not offered in this preset: set to No","OK")) -> OK
A19: =IF(E19="Yes","A","-") -> - | B19: Annex: Means of verification | C19: A Evidence | D19: =INDEX(Guide!$C$22:$G$34,12,MATCH(About!$B$8,Guide!$C$20:$G$20,0)) -> Optional | E19: No | F19: =IF(AND(D19="Required",E19<>"Yes"),"Required by this preset: set to Yes",IF(AND(D19="Not offered",E19="Yes"),"Not offered in this preset: set to No","OK")) -> OK
A20: =IF(E20="Yes",IF(E19="Yes","B","A"),"-") -> - | B20: Annex: Data tables | C20: B Data tables | D20: =INDEX(Guide!$C$22:$G$34,13,MATCH(About!$B$8,Guide!$C$20:$G$20,0)) -> Optional | E20: No | F20: =IF(AND(D20="Required",E20<>"Yes"),"Required by this preset: set to Yes",IF(AND(D20="Not offered",E20="Yes"),"Not offered in this preset: set to No","OK")) -> OK
A21: =CHAR(65+COUNTIF(E19:E20,"Yes")) -> A | B21: Annex: Definitions and method | C21: C Definitions | D21: Always | E21: Yes
B22: Sign-off | C22: Sign-off | D22: Always | E22: Yes

Sheet 1 Summary
A1: ="PATHWAYS | "&About!$B$7&" "&About!$B$6&" | "&About!$B$8&" report" -> PATHWAYS | CLP-2025-03 Coastal Livelihoods Project | Midterm report
A2: =IF(Contents!$E$8="Yes",Contents!$A$8&" ","[Not included] ")&"Executive summary" -> 1 Executive summary
A3: Required in every preset. Status and key figures are computed; the summary text is editable.
A5: Overall status | B5: =IF(COUNTIF('3 Status'!B6:B9,"Off track")>0,"Off track",IF(COUNTIF('3 Status'!B6:B9,"At risk")>0,"At risk","On track")) -> At risk | C5: Worst status across Schedule, Budget, Indicators and Reach
A7: Key figures
A8: Figure | B8: Value | C8: Detail | D8: Gap vs timeline
A9: Timeline elapsed | B9: =About!$B$14 -> 0.49931413 | C9: =TEXT(About!$B$12,"d mmm yyyy")&" to "&TEXT(About!$B$13,"d mmm yyyy") -> 1 Oct 2025 to 30 Sep 2027
A10: Budget used | B10: ='8 Budget'!$D$11 -> 0.46 | C10: ="PHP "&TEXT('8 Budget'!C11,"#,##0")&" of "&TEXT('8 Budget'!B11,"#,##0") -> PHP 5,520,000 of 12,000,000 | D10: =B10-B9 -> -0.039314129
A11: KPI achievement | B11: ='4 Indicators'!$H$13 -> 0.465 | C11: Average progress across indicators | D11: =B11-B9 -> -0.034314129
A12: Beneficiaries reached | B12: ='6 Reach'!$C$20 -> 742 | C12: =TEXT('6 Reach'!$C$31,"0%")&" of "&TEXT('2 Background'!$B$15,"#,##0")&" target" -> 62% of 1,200 target | D12: ='6 Reach'!$C$31-B9 -> 0.1190192
A14: Data-drafted summary (computed)
A15: ="As of "&TEXT(About!$B$11,"d mmm yyyy")&", the project is "&TEXT(B9,"0%")&" through its timeline, has used "&TEXT(B10,"0%")&" of its approved budget, has reached "&TEXT(B12,"#,##0")&" beneficiaries ("&TEXT('6 Reach'!$C$31,"0%")&" of target), and averages "&TEXT(B11,"0%")&" progress across its indicators." -> As of 30 Sep 2026, the project is 50% through its timeline, has used 46% of its approved budget, has reached 742 beneficiaries (62% of target), and averages 47% progress across its indicators.
A17: Executive summary (editable)
A18: [Copy the computed summary above, then add the one achievement and the one risk the reader must know, and what the project will do about the risk.]

Sheet 2 Background
A1: ="PATHWAYS | "&About!$B$7&" "&About!$B$6&" | "&About!$B$8&" report" -> PATHWAYS | CLP-2025-03 Coastal Livelihoods Project | Midterm report
A2: =IF(Contents!$E$9="Yes",Contents!$A$9&" ","[Not included] ")&"Project background" -> 2 Project background
A3: Auto section with one editable block. Source: project record.
A5: Item | B5: Detail
A6: Project code | B6: =About!B7 -> CLP-2025-03
A7: Project title | B7: =About!B6 -> Coastal Livelihoods Project
A8: Status | B8: Ongoing
A9: Sector | B9: Livelihoods and economic empowerment
A10: Implementation area | B10: Borongan, Guiuan, Salcedo and Mercedes, Eastern Samar
A11: Start date | B11: =About!B12 -> 45931
A12: End date | B12: =About!B13 -> 46660
A13: Implementing partners | B13: Two municipal LGUs and one cooperative federation
A14: Program manager | B14: Program Manager (role shown, not name)
A15: Target beneficiaries | B15: 1200
A17: Objectives
A18: Increase household income of coastal women through skills training, savings groups and start-up support for small enterprises, so families depend less on seasonal fishing.

Sheet 3 Status
A1: ="PATHWAYS | "&About!$B$7&" "&About!$B$6&" | "&About!$B$8&" report" -> PATHWAYS | CLP-2025-03 Coastal Livelihoods Project | Midterm report
A2: =IF(Contents!$E$10="Yes",Contents!$A$10&" ","[Not included] ")&"Status overview" -> 3 Status overview
A3: Auto section. Status is computed by the rules in Annex C; the comment column is editable.
A5: Area | B5: Status | C5: Basis | D5: Comment
A6: Schedule | B6: =IF('5 Activities'!$B$16>30,"Off track",IF('5 Activities'!$B$16>0,"At risk","On track")) -> At risk | C6: ="Longest overdue milestone: "&'5 Activities'!$B$16&" days" -> Longest overdue milestone: 18 days | D6: Kit procurement batch 2 delayed by supplier stock-out.
A7: Budget | B7: =IF('8 Budget'!$D$11>1,"Off track",IF('8 Budget'!$D$11-About!$B$14>0.15,"At risk","On track")) -> On track | C7: =TEXT('8 Budget'!$D$11,"0%")&" used vs "&TEXT(About!$B$14,"0%")&" of timeline elapsed" -> 46% used vs 50% of timeline elapsed | D7: Spend follows the work plan.
A8: Indicators | B8: =IF(About!$B$14-'4 Indicators'!$H$13>0.25,"Off track",IF(About!$B$14-'4 Indicators'!$H$13>0.1,"At risk","On track")) -> On track | C8: ="Average indicator progress "&TEXT('4 Indicators'!$H$13,"0%")&" vs "&TEXT(About!$B$14,"0%")&" elapsed" -> Average indicator progress 47% vs 50% elapsed | D8: Outcome indicators lag until enterprises mature.
A9: Reach | B9: =IF(About!$B$14-'6 Reach'!$C$31>0.25,"Off track",IF(About!$B$14-'6 Reach'!$C$31>0.1,"At risk","On track")) -> On track | C9: =TEXT('6 Reach'!$C$31,"0%")&" of target reached vs "&TEXT(About!$B$14,"0%")&" elapsed" -> 62% of target reached vs 50% elapsed | D9: Cohort 3 enrolment opens in November.
A10: Status rules: Annex C Definitions and method.

Sheet 4 Indicators
A1: ="PATHWAYS | "&About!$B$7&" "&About!$B$6&" | "&About!$B$8&" report" -> PATHWAYS | CLP-2025-03 Coastal Livelihoods Project | Midterm report
A2: =IF(Contents!$E$11="Yes",Contents!$A$11&" ","[Not included] ")&"Results and indicator performance" -> 4 Results and indicator performance
A3: Auto section. Progress and status are computed; write a variance explanation for every indicator not On track.
A5: Code | B5: Indicator | C5: Type | D5: Unit | E5: Baseline | F5: Target | G5: Current | H5: Progress | I5: Status | J5: Variance explanation
A6: OC1 | B6: Trained women reporting higher monthly household income | C6: Outcome | D6: percent | E6: 0 | F6: 0.6 | G6: 0.22 | H6: =IF(F6=E6,"Not available",(G6-E6)/(F6-E6)) -> 0.36666667 | I6: =IF(ISNUMBER(H6),IF(About!$B$14-H6>0.25,"Off track",IF(About!$B$14-H6>0.1,"At risk","On track")),"Not available") -> At risk | J6: [Explain the gap and the corrective action with a date.]
A7: OC2 | B7: Women-led enterprises operating 6 months after start-up | C7: Outcome | D7: number | E7: 0 | F7: 150 | G7: 35 | H7: =IF(F7=E7,"Not available",(G7-E7)/(F7-E7)) -> 0.23333333 | I7: =IF(ISNUMBER(H7),IF(About!$B$14-H7>0.25,"Off track",IF(About!$B$14-H7>0.1,"At risk","On track")),"Not available") -> Off track | J7: [Explain the gap and the corrective action with a date.]
A8: OP1 | B8: Women completing livelihood skills training | C8: Output | D8: number | E8: 0 | F8: 900 | G8: 612 | H8: =IF(F8=E8,"Not available",(G8-E8)/(F8-E8)) -> 0.68 | I8: =IF(ISNUMBER(H8),IF(About!$B$14-H8>0.25,"Off track",IF(About!$B$14-H8>0.1,"At risk","On track")),"Not available") -> On track
A9: OP2 | B9: Savings groups formed and registered | C9: Output | D9: number | E9: 0 | F9: 40 | G9: 26 | H9: =IF(F9=E9,"Not available",(G9-E9)/(F9-E9)) -> 0.65 | I9: =IF(ISNUMBER(H9),IF(About!$B$14-H9>0.25,"Off track",IF(About!$B$14-H9>0.1,"At risk","On track")),"Not available") -> On track
A10: OP3 | B10: Start-up kits distributed | C10: Output | D10: number | E10: 0 | F10: 300 | G10: 118 | H10: =IF(F10=E10,"Not available",(G10-E10)/(F10-E10)) -> 0.39333333 | I10: =IF(ISNUMBER(H10),IF(About!$B$14-H10>0.25,"Off track",IF(About!$B$14-H10>0.1,"At risk","On track")),"Not available") -> At risk | J10: Batch 2 delayed by a supplier stock-out; 82 kits due for distribution in October.
A11: AC1 | B11: Activity completion (derived) | C11: Activity | D11: percent | E11: 0 | F11: 1 | G11: ='5 Activities'!B15 -> 0.46666667 | H11: =IF(F11=E11,"Not available",(G11-E11)/(F11-E11)) -> 0.46666667 | I11: =IF(ISNUMBER(H11),IF(About!$B$14-H11>0.25,"Off track",IF(About!$B$14-H11>0.1,"At risk","On track")),"Not available") -> On track
A13: KPI achievement (average indicator progress) | H13: =AVERAGE(H6:H11) -> 0.465 | I13: =IF(About!$B$14-H13>0.25,"Off track",IF(About!$B$14-H13>0.1,"At risk","On track")) -> On track
A14: ="Source: indicator measurements and derived activity completion, "&TEXT(About!$B$9,"d mmm yyyy")&" to "&TEXT(About!$B$10,"d mmm yyyy")&". Status compares progress with timeline elapsed ("&TEXT(About!$B$14,"0%")&")." -> Source: indicator measurements and derived activity completion, 1 Oct 2025 to 30 Sep 2026. Status compares progress with timeline elapsed (50%).

Sheet 5 Activities
A1: ="PATHWAYS | "&About!$B$7&" "&About!$B$6&" | "&About!$B$8&" report" -> PATHWAYS | CLP-2025-03 Coastal Livelihoods Project | Midterm report
A2: =IF(Contents!$E$12="Yes",Contents!$A$12&" ","[Not included] ")&"Activities and milestones" -> 5 Activities and milestones
A3: Auto section. Status and days overdue are computed against the data cut-off.
A5: Milestone | B5: Target date | C5: Completion date | D5: Status | E5: Days overdue | F5: Note
A6: Baseline survey completed | B6: 46006 | C6: 46003 | D6: =IF(C6<>"",IF(C6>B6,"Completed late","Completed"),IF(B6<About!$B$11,"Overdue","Planned")) -> Completed | E6: =IF(AND(C6="",B6<About!$B$11),About!$B$11-B6,0) -> 0
A7: Cohort 1 training completed | B7: 46112 | C7: 46112 | D7: =IF(C7<>"",IF(C7>B7,"Completed late","Completed"),IF(B7<About!$B$11,"Overdue","Planned")) -> Completed | E7: =IF(AND(C7="",B7<About!$B$11),About!$B$11-B7,0) -> 0
A8: Savings groups registered with LGU | B8: 46203 | C8: 46208 | D8: =IF(C8<>"",IF(C8>B8,"Completed late","Completed"),IF(B8<About!$B$11,"Overdue","Planned")) -> Completed late | E8: =IF(AND(C8="",B8<About!$B$11),About!$B$11-B8,0) -> 0 | F8: LGU session moved by one week.
A9: Start-up kit procurement, batch 2 | B9: 46277 | D9: =IF(C9<>"",IF(C9>B9,"Completed late","Completed"),IF(B9<About!$B$11,"Overdue","Planned")) -> Overdue | E9: =IF(AND(C9="",B9<About!$B$11),About!$B$11-B9,0) -> 18 | F9: Supplier stock-out; extension approved to 31 Oct 2026.
A10: Midterm review workshop | B10: 46315 | D10: =IF(C10<>"",IF(C10>B10,"Completed late","Completed"),IF(B10<About!$B$11,"Overdue","Planned")) -> Planned | E10: =IF(AND(C10="",B10<About!$B$11),About!$B$11-B10,0) -> 0
A12: Activity summary
A13: Activities planned | B13: 30
A14: Activities completed | B14: 14
A15: Activity completion | B15: =IF(B13=0,0,B14/B13) -> 0.46666667
A16: Longest overdue milestone (days) | B16: =MAX(E6:E10) -> 18
A18: Delays and extension requests
A19: 1 overdue explanation filed (kit procurement, supplier stock-out). 1 extension request approved: batch 2 distribution moved to 31 Oct 2026.
A20: Source: project milestones, verified activity updates, overdue explanations and extension requests.

Sheet 6 Reach
A1: ="PATHWAYS | "&About!$B$7&" "&About!$B$6&" | "&About!$B$8&" report" -> PATHWAYS | CLP-2025-03 Coastal Livelihoods Project | Midterm report
A2: =IF(Contents!$E$13="Yes",Contents!$A$13&" ","[Not included] ")&"Beneficiary reach" -> 6 Beneficiary reach
A3: Auto section, aggregates only. Groups under 5 are suppressed and never shown as zero.
A5: Dimension | B5: Category | C5: People | D5: Share
A6: Sex | B6: Female | C6: 618 | D6: =IF(ISNUMBER(C6),C6/$C$20,"-") -> 0.8328841
B7: Male | C7: 120 | D7: =IF(ISNUMBER(C7),C7/$C$20,"-") -> 0.16172507
B8: Not recorded | C8: Fewer than 5 | D8: =IF(ISNUMBER(C8),C8/$C$20,"-") -> -
A9: Age | B9: 18 to 24 | C9: 131 | D9: =IF(ISNUMBER(C9),C9/$C$20,"-") -> 0.17654987
B10: 25 to 39 | C10: 344 | D10: =IF(ISNUMBER(C10),C10/$C$20,"-") -> 0.46361186
B11: 40 to 59 | C11: 228 | D11: =IF(ISNUMBER(C11),C11/$C$20,"-") -> 0.30727763
B12: 60 and over | C12: 39 | D12: =IF(ISNUMBER(C12),C12/$C$20,"-") -> 0.052560647
A13: Disability | B13: With disability | C13: 46 | D13: =IF(ISNUMBER(C13),C13/$C$20,"-") -> 0.061994609
B14: Without disability | C14: 689 | D14: =IF(ISNUMBER(C14),C14/$C$20,"-") -> 0.92857143
B15: Not recorded | C15: 7 | D15: =IF(ISNUMBER(C15),C15/$C$20,"-") -> 0.0094339623
A16: Location | B16: Borongan | C16: 248 | D16: =IF(ISNUMBER(C16),C16/$C$20,"-") -> 0.33423181
B17: Guiuan | C17: 201 | D17: =IF(ISNUMBER(C17),C17/$C$20,"-") -> 0.27088949
B18: Salcedo | C18: 167 | D18: =IF(ISNUMBER(C18),C18/$C$20,"-") -> 0.22506739
B19: Mercedes | C19: 126 | D19: =IF(ISNUMBER(C19),C19/$C$20,"-") -> 0.16981132
A20: Total reached | B20: Released aggregate | C20: 742 | D20: =C20/C20 -> 1
A21: Source: released beneficiary aggregates (SADDD). Shares use the released total; suppressed groups are excluded from shares.
A23: Journey stage progression
A24: Stage | C24: People | D24: Of registered
A25: Registered | C25: 980 | D25: =C25/$C$25 -> 1
A26: Enrolled | C26: 742 | D26: =C26/$C$25 -> 0.75714286
A27: Training completed | C27: 612 | D27: =C27/$C$25 -> 0.6244898
A28: Enterprise started | C28: 118 | D28: =C28/$C$25 -> 0.12040816
A29: Operating at 6 months | C29: 35 | D29: =C29/$C$25 -> 0.035714286
A31: Reach against target | C31: =C20/'2 Background'!$B$15 -> 0.61833333 | D31: ="of "&TEXT('2 Background'!$B$15,"#,##0")&" target" -> of 1,200 target

Sheet 7 Assessment
A1: ="PATHWAYS | "&About!$B$7&" "&About!$B$6&" | "&About!$B$8&" report" -> PATHWAYS | CLP-2025-03 Coastal Livelihoods Project | Midterm report
A2: =IF(Contents!$E$14="Yes",Contents!$A$14&" ","[Not included] ")&"Survey and assessment results" -> [Not included] Survey and assessment results
A3: Conditional section: included only when published assessment results exist for the period.
A5: Assessment | B5: Matched pairs | C5: Pre-test mean | D5: Post-test mean | E5: Gain (points)
A6: Enterprise basics and bookkeeping | B6: 588 | C6: 54.2 | D6: 76.8 | E6: =D6-C6 -> 22.6
A7: Source: pre-test and post-test results for participants with both scores.
A9: Interpretation
A10: [What does the gain mean for the outcome indicators?]

Sheet 8 Budget
A1: ="PATHWAYS | "&About!$B$7&" "&About!$B$6&" | "&About!$B$8&" report" -> PATHWAYS | CLP-2025-03 Coastal Livelihoods Project | Midterm report
A2: =IF(Contents!$E$15="Yes",Contents!$A$15&" ","[Not included] ")&"Financial summary" -> 7 Financial summary
A3: Auto section. Spent counts verified and approved expenses only.
A5: Category | B5: Approved budget (PHP) | C5: Spent (PHP) | D5: Used | E5: Balance (PHP) | F5: Used minus timeline
A6: Training and capacity building | B6: 3200000 | C6: 1940000 | D6: =IF(B6=0,"Not available",C6/B6) -> 0.60625 | E6: =B6-C6 -> 1260000 | F6: =IF(ISNUMBER(D6),D6-About!$B$14,"") -> 0.10693587
A7: Start-up kits | B7: 4500000 | C7: 1310000 | D7: =IF(B7=0,"Not available",C7/B7) -> 0.29111111 | E7: =B7-C7 -> 3190000 | F7: =IF(ISNUMBER(D7),D7-About!$B$14,"") -> -0.20820302
A8: Personnel | B8: 2400000 | C8: 1250000 | D8: =IF(B8=0,"Not available",C8/B8) -> 0.52083333 | E8: =B8-C8 -> 1150000 | F8: =IF(ISNUMBER(D8),D8-About!$B$14,"") -> 0.021519204
A9: Monitoring and evaluation | B9: 900000 | C9: 520000 | D9: =IF(B9=0,"Not available",C9/B9) -> 0.57777778 | E9: =B9-C9 -> 380000 | F9: =IF(ISNUMBER(D9),D9-About!$B$14,"") -> 0.078463649
A10: Administration and logistics | B10: 1000000 | C10: 500000 | D10: =IF(B10=0,"Not available",C10/B10) -> 0.5 | E10: =B10-C10 -> 500000 | F10: =IF(ISNUMBER(D10),D10-About!$B$14,"") -> 0.00068587106
A11: Total | B11: =SUM(B6:B10) -> 12000000 | C11: =SUM(C6:C10) -> 5520000 | D11: =IF(B11=0,"Not available",C11/B11) -> 0.46 | E11: =B11-C11 -> 6480000 | F11: =D11-About!$B$14 -> -0.039314129
A13: Pending expenses (excluded from Spent)
A14: Count | B14: 3
A15: Amount (PHP) | B15: 184500
A16: Source: approved project budget records and expense entries with VERIFIED or APPROVED status.
A18: Financial commentary
A19: Start-up kit spend is low because batch 2 is delayed; it should reach about 50% once the October distribution is paid. [Note any planned budget realignment.]

Sheet 9 Evaluation
A1: ="PATHWAYS | "&About!$B$7&" "&About!$B$6&" | "&About!$B$8&" report" -> PATHWAYS | CLP-2025-03 Coastal Livelihoods Project | Midterm report
A2: =IF(Contents!$E$16="Yes",Contents!$A$16&" ","[Not included] ")&"Evaluation" -> 8 Evaluation
A3: Conditional section: included only when a signed-off or archived evaluation exists for the period.
A5: Criterion | B5: Weight | C5: Score | D5: Maximum | E5: Weighted score
A6: KPI achievement | B6: 0.3 | C6: 3 | D6: 5 | E6: =B6*C6 -> 0.9
A7: Timeline compliance | B7: 0.2 | C7: 4 | D7: 5 | E7: =B7*C7 -> 0.8
A8: Budget efficiency | B8: 0.2 | C8: 4 | D8: 5 | E8: =B8*C8 -> 0.8
A9: Beneficiary reach | B9: 0.2 | C9: 4 | D9: 5 | E9: =B9*C9 -> 0.8
A10: Assessment gain | B10: 0.1 | C10: 5 | D10: 5 | E10: =B10*C10 -> 0.5
A11: Overall | B11: =SUM(B6:B10) -> 1 | D11: 5 | E11: =SUM(E6:E10) -> 3.8
A12: Overall percent | E12: =IF(D11=0,"Not available",E11/D11) -> 0.76
A13: =IF(ROUND(B11,4)=1,"Weights total 100%","Check: weights must total 100%") -> Weights total 100%
A14: Source: midterm evaluation, signed off 30 Sep 2026.

Sheet 10 Risks
A1: ="PATHWAYS | "&About!$B$7&" "&About!$B$6&" | "&About!$B$8&" report" -> PATHWAYS | CLP-2025-03 Coastal Livelihoods Project | Midterm report
A2: =IF(Contents!$E$17="Yes",Contents!$A$17&" ","[Not included] ")&"Risks, issues and decisions" -> 9 Risks, issues and decisions
A3: Conditional section: open alerts and decisions come from the rules engine; add other risks in the yellow rows.
A5: Type | B5: Item | C5: Severity or status | D5: Mitigation or next step
A6: Alert | B6: Start-up kit distribution behind schedule | C6: High | D6: Local supplier sourced for batch 3.
A7: Alert | B7: Enterprise survival indicator below trajectory | C7: Medium | D7: [Mitigation]
A8: Decision | B8: Source kit batch 3 from a local supplier | C8: Approved | D8: Contract signed 28 Sep 2026.
A9: Decision | B9: Add mentoring visits in enterprise months 3 to 6 | C9: Proposed | D9: [Next step]
A10: Other risk | B10: [Risk not raised by system alerts] | C10: [Severity] | D10: [Mitigation]
A11: Other risk
A12: Source: open rule-based alerts (highest severity first, up to 10) and decision recommendations.

Sheet 11 Lessons
A1: ="PATHWAYS | "&About!$B$7&" "&About!$B$6&" | "&About!$B$8&" report" -> PATHWAYS | CLP-2025-03 Coastal Livelihoods Project | Midterm report
A2: =IF(Contents!$E$18="Yes",Contents!$A$18&" ","[Not included] ")&"Lessons learned and next steps" -> 10 Lessons learned and next steps
A3: Narrative section. All blocks are editable.
A5: Challenges
A6: [What slowed the project down this period?]
A8: Lessons learned
A9: Savings groups formed faster where barangay officials co-hosted the first meeting.
A11: Recommendations
A12: [What should management or the donor change?]
A14: Next-period priorities
A15: Distribute 82 batch-2 kits by 31 Oct 2026; open Cohort 3 enrolment; start enterprise mentoring visits.

Sheet A Evidence
A1: ="PATHWAYS | "&About!$B$7&" "&About!$B$6&" | "&About!$B$8&" report" -> PATHWAYS | CLP-2025-03 Coastal Livelihoods Project | Midterm report
A2: =IF(Contents!$E$19="Yes","Annex "&Contents!$A$19&" ","[Not included] ")&"Means of verification" -> [Not included] Means of verification
A3: Auto annex. Only approved evidence appears; identifying items are listed, never shown as images.
A5: Ref | B5: Evidence | C5: Type | D5: Supports | E5: Date | F5: Identifying | G5: In PDF and DOCX
A6: EV-0412 | B6: Attendance sheets, Cohort 2 training | C6: Document | D6: OP1 | E6: 46248 | F6: No | G6: =IF(F6="Yes","Listed only",IF(C6="Photo","Shown as thumbnail","Listed")) -> Listed
A7: EV-0388 | B7: Savings group registration certificates | C7: Document | D7: OP2 | E7: 46208 | F7: No | G7: =IF(F7="Yes","Listed only",IF(C7="Photo","Shown as thumbnail","Listed")) -> Listed
A8: EV-0455 | B8: Kit distribution, Guiuan | C8: Photo | D8: OP3 | E8: 46267 | F8: No | G8: =IF(F8="Yes","Listed only",IF(C8="Photo","Shown as thumbnail","Listed")) -> Shown as thumbnail
A9: EV-0461 | B9: Outcome monitoring survey summary | C9: Document | D9: OC1 | E9: 46290 | F9: No | G9: =IF(F9="Yes","Listed only",IF(C9="Photo","Shown as thumbnail","Listed")) -> Listed
A10: EV-0470 | B10: Enterprise owner at her stall | C10: Photo | D10: OC2 | E10: 46292 | F10: Yes | G10: =IF(F10="Yes","Listed only",IF(C10="Photo","Shown as thumbnail","Listed")) -> Listed only
A11: Source: approved evidence media linked to indicators and activities in the report period.

Sheet B Data tables
A1: ="PATHWAYS | "&About!$B$7&" "&About!$B$6&" | "&About!$B$8&" report" -> PATHWAYS | CLP-2025-03 Coastal Livelihoods Project | Midterm report
A2: =IF(Contents!$E$20="Yes","Annex "&Contents!$A$20&" ","[Not included] ")&"Data tables" -> [Not included] Data tables
A3: Auto annex. PATHWAYS adds the full tables behind each included section here when exporting.
A5: - Indicator measurement history (every period value and correction)
A6: - All activities with planned and actual dates, progress and beneficiaries per session
A7: - Expense totals by month and category
A8: - Survey item results (respondents, answered, missing, mean)

Sheet C Definitions
A1: ="PATHWAYS | "&About!$B$7&" "&About!$B$6&" | "&About!$B$8&" report" -> PATHWAYS | CLP-2025-03 Coastal Livelihoods Project | Midterm report
A2: ="Annex "&Contents!$A$21&" Definitions and method" -> Annex A Definitions and method
A3: Fixed annex. Always present.
A5: Term | B5: Definition
A6: Status: Schedule | B6: Off track when a milestone is more than 30 days overdue; at risk when any milestone is overdue.
A7: Status: Budget | B7: Off track above 100% used; at risk when budget used runs more than 15 points ahead of timeline elapsed.
A8: Status: Indicators | B8: At risk when progress is more than 10 points behind timeline elapsed; off track when more than 25 behind.
A9: Status: Reach | B9: Same thresholds as Indicators, using reach against target.
A10: Timeline elapsed | B10: Days from project start to the data cut-off, divided by the project's total days.
A11: Progress | B11: (Current - Baseline) / (Target - Baseline).
A12: Not available | B12: A value could not be computed from verified records. It is never shown as zero.
A13: Fewer than 5 | B13: A group too small to report without risk of identifying people.
A14: Derived indicator | B14: Calculated by PATHWAYS from records, such as activity completion, rather than entered by hand.

Sheet Sign-off
A1: ="PATHWAYS | "&About!$B$7&" "&About!$B$6&" | "&About!$B$8&" report" -> PATHWAYS | CLP-2025-03 Coastal Livelihoods Project | Midterm report
A2: Sign-off
A3: Editable. Fill in before sharing the final version.
A5: Step | B5: Name | C5: Position | D5: Date | E5: Signature
A6: Prepared by
A7: Reviewed by
A8: Approved by

Sheet Guide
A1: ="PATHWAYS | "&About!$B$7&" "&About!$B$6&" | "&About!$B$8&" report" -> PATHWAYS | CLP-2025-03 Coastal Livelihoods Project | Midterm report
A2: Template guide
A3: How this template works. PATHWAYS fills the blue cells when a report is generated; people write in the yellow cells.
A5: Cell legend
A6: Yellow fill | B6: Editable. Write or replace the text; starter text and [prompts] are suggestions.
A7: Blue fill | B7: System data. Filled by PATHWAYS from verified records at generation; sample values are fictional.
A8: No fill | B8: Formula or fixed text. Computed from other cells; do not overwrite.
A9: Grey italic | B9: Fixed wording that must stay, such as definitions and privacy notices.
A11: Steps
A12: 1. On About, pick the report preset, period and filters.
A13: 2. On Contents, set Include to Yes or No per section. Required sections must stay Yes; the Check column flags mistakes.
A14: 3. Excluded sections renumber automatically; their sheets show [Not included] and are skipped on export.
A15: 4. Write the yellow narrative cells, starting with the Executive summary and the variance explanations.
A16: 5. Never type over a blue or formula cell; regenerate the report in PATHWAYS if the numbers are wrong.
A18: Sections by preset
A19: Required = locked on. Default = on unless removed. Optional = off unless added. Not offered = hidden in that preset.
A20: Section | B20: Sheet | C20: Midterm | D20: Evidence (M&E) | E20: Quarterly progress | F20: Final | G20: Donor brief
A21: Cover overline | C21: MIDTERM REPORT | D21: EVIDENCE REPORT | E21: QUARTERLY PROGRESS REPORT | F21: END-OF-PROJECT REPORT | G21: DONOR BRIEF
A22: 1 Executive summary | B22: 1 Summary | C22: Required | D22: Required | E22: Required | F22: Required | G22: Required
A23: 2 Project background | B23: 2 Background | C23: Default | D23: Optional | E23: Optional | F23: Default | G23: Default
A24: 3 Status overview | B24: 3 Status | C24: Default | D24: Default | E24: Default | F24: Default | G24: Default
A25: 4 Results and indicator performance | B25: 4 Indicators | C25: Default | D25: Required | E25: Default | F25: Default | G25: Default
A26: 5 Activities and milestones | B26: 5 Activities | C26: Default | D26: Default | E26: Default | F26: Default | G26: Optional
A27: 6 Beneficiary reach | B27: 6 Reach | C27: Default | D27: Default | E27: Default | F27: Default | G27: Default
A28: 7 Survey and assessment results | B28: 7 Assessment | C28: Optional | D28: Default | E28: Optional | F28: Default | G28: Optional
A29: 8 Financial summary | B29: 8 Budget | C29: Default | D29: Optional | E29: Default | F29: Default | G29: Default
A30: 9 Evaluation | B30: 9 Evaluation | C30: Default | D30: Optional | E30: Not offered | F30: Required | G30: Optional
A31: 10 Risks, issues and decisions | B31: 10 Risks | C31: Default | D31: Optional | E31: Default | F31: Optional | G31: Not offered
A32: 11 Lessons learned and next steps | B32: 11 Lessons | C32: Default | D32: Optional | E32: Default | F32: Default | G32: Optional
A33: Annex A Means of verification | B33: A Evidence | C33: Optional | D33: Required | E33: Optional | F33: Default | G33: Not offered
A34: Annex B Data tables | B34: B Data tables | C34: Optional | D34: Default | E34: Optional | F34: Default | G34: Not offered
A35: Default period | C35: Project start to midpoint | D35: Last quarter | E35: Last quarter | F35: Whole project | G35: Project start to report date
A37: Always present
A38: - Cover, About this report, the Executive summary status and key figures, Annex C Definitions and method, and the Sign-off block.
A39: - A section the user has no access to is left out without comment.
A40: - A selected section with no records stays in and says so, for example "No milestones in this period."
A41: - Groups under 5 people show "Fewer than 5". A missing value shows "Not available", never zero.
A42: - Every table carries a source line naming the records and the period.
A44: Export formats
A45: - PDF: the designed document, one section per heading, charts included.
...
